Workbook
Name GRAND: #REF!
Name Print_Area_MI: #REF!
Name Print_Titles_MI: #REF!,#REF!

Sheet G702
A1: APPLICATION AND CERTIFICATION FOR PAYMENT | G1: AIA DOCUMENT G702 | P1: Print
A3: TO OWNER: | D3: PROJECT: | H3: APPLICATION NO: | I3: 17 | K3: Distribution to: | P3: 0
A5: Prevail Waxahachie, LLC | D5: Residence Inn | H5: PERIOD TO: | I5: 46086 | K5: X | L5: OWNER
D7: Waxahachie, Texas | H7: CONTRACT DATE: | I7: 45461 | L7: ARCHITECT
L9: CONTRACTOR
A11: FROM CONTRACTOR: | D11: VIA ARCHITECT:
A13: Divine Force JD RI Waxahachie, LLC | D13: Maust Architectural Services
A17: CONTRACT FOR:
A19: CONTRACTOR'S APPLICATION FOR PAYMENT | G19: The undersigned Contractor certifies that to the best of the Contractor's knowledge,
A20: Application is made for payment, as shown below, in connection with the Contract. | G20: information and belief the Work covered by this Application for Payment has been
A21: Continuation Sheet, AIA Document G703, is attached. | G21: completed in accordance with the Contract Documents, that all amounts have been paid by
G22: the Contractor for Work for which previous Certificates for Payment were issued and
G23: payments received from the Owner, and that current payment shown herein is now due.
A25: 1. ORIGINAL CONTRACT SUM | E25: 11800000
A26: 2. Net change by Change Orders | E26: 0 | G26: CONTRACTOR:
A27: 3. CONTRACT SUM TO DATE (Line 1 ± 2) | E27: =+SUM(E25,E26) -> 11800000
A28: 4. TOTAL COMPLETED & STORED TO | E28: =+'G703'!G32 -> 11347285
A29: DATE (Column G on G703) | G29: By: | K29: Date:
A30: 5. RETAINAGE:
A31: a. | C31: % of Completed Work $ | G31: State of: | J31: County of:
B32: (Column D + E on G703) | G32: Subscribed and sworn to before me this | J32: day of
A33: b. | C33: % of Stored Material $ | G33: Notary Public:
B34: (Column F on G703) | G34: My Commission expires:
A35: Total Retainage (Lines 5a + 5b or
B36: Total in Column I of G703) | D36: $ | E36: =+'G703'!J32 -> 539680.01 | G36: ARCHITECT'S CERTIFICATE FOR PAYMENT
A37: 6. TOTAL EARNED LESS RETAINAGE | D37: $ | E37: =+E28-E36 -> 10807605 | G37: In accordance with the Contract Documents, based on on-site observations and the data
B38: (Line 4 Less Line 5 Total) | G38: comprising the application, the Architect certifies to the Owner that to the best of the
A39: 7. LESS PREVIOUS CERTIFICATES FOR | G39: Architect's knowledge, information and belief the Work has progressed as indicated,
A40: PAYMENT (Line 6 from prior Certificate) | D40: $ | E40: =+SUMIFS('Boulder Invoice'!$J:$J,'Boulder Invoice'!$B:$B,"<"&$I$3) -> 10083916 | G40: the quality of the Work is in accordance with the Contract Documents, and the Contractor
A41: 8. CURRENT PAYMENT DUE | D41: $ | E41: =+E37-E40 -> 723689.65 | G41: is entitled to payment of the AMOUNT CERTIFIED.
A42: 9. BALANCE TO FINISH, INCLUDING RETAINAGE $ | E42: =+E27-E37 -> 992394.79
B43: (Line 3 less Line 6) | G43: AMOUNT CERTIFIED . . . . . . . . . . . $
A45: CHANGE ORDER SUMMARY | D45: ADDITIONS | E45: DEDUCTIONS | G45: (Attach explanation if amount certified differs from the amount applied. Initial all figures on this
A46: Total changes approved | G46: Application and onthe Continuation Sheet that are changed to conform with the amount certified.)
A47: in previous months by Owner | D47: 0 | E47: 0 | G47: ARCHITECT:
A49: Total approved this Month | D49: 0 | E49: 0 | G49: By: | K49: Date:
A51: TOTALS | D51: =+D47+D49 -> 0 | E51: =+E47+E49 -> 0 | G51: This Certificate is not negotiable. The AMOUNT CERTIFIED is payable only to the
G52: Contractor named herein. Issuance, payment and acceptance of payment are without
A53: NET CHANGES by Change Order | D53: =+D51-E51 -> 0 | G53: prejudice to any rights of the Owner or Contractor under this Contract.
A55: AIA DOCUMENT G702 · APPLICATION AND CERTIFICATION FOR PAYMENT · 1992 EDITION · AIA® · © 1992 | G55: THE AMERICAN INSTITUTE OF ARCHITECTS, 1735 NEW YORK AVE., N.W., WASHINGTON, DC 20006-5292
...

Sheet G703
A1: CONTINUATION SHEET | E1: AIA DOCUMENT G703 | L1: Print
A2: AIA Document G702, APPLICATION AND CERTIFICATION FOR PAYMENT, containing | H2: APPLICATION NO: | I2: =+'G702'!I3 -> 17 | L2: =+'G702'!P3 -> 0
A3: Contractor's signed certification is attached. | H3: APPLICATION DATE: | I3: =+'G702'!I5 -> 46086
A4: In tabulations below, amounts are stated to the nearest dollar. | H4: PERIOD TO: | I4: =+I3 -> 46086
A5: Use Column I on Contracts where variable retainage for line items may apply. | H5: PROJECT NO:
A7: A | B7: B | C7: C | D7: D | E7: E | F7: F | G7: G | I7: H | J7: I
D8: WORK COMPLETED | F8: MATERIALS | G8: TOTAL
A9: ITEM | B9: DESCRIPTION OF WORK | C9: SCHEDULED | D9: FROM PREVIOUS | F9: PRESENTLY | G9: COMPLETED | H9: % | I9: BALANCE | J9: RETAINAGE
A10: NO. | C10: VALUE | D10: APPLICATION | E10: THIS PERIOD | F10: STORED | G10: AND STORED | H10: (G ÷ C) | I10: TO FINISH | J10: (IF VARIABLE
D11: (D + E) | F11: (NOT IN | G11: TO DATE | I11: (C - G) | J11: RATE)
F12: D OR E) | G12: (D+E+F)
A13: 1 | B13: GENERAL CONDITIONS | C13: 650000 | D13: =+SUMIFS('Boulder Invoice'!$H:$H,'Boulder Invoice'!$B:$B,"<"&$I$2,'Boulder Invoice'!$E:$E,$A13) -> 603546.8 | E13: =+SUMIFS('Boulder Invoice'!$H:$H,'Boulder Invoice'!$B:$B,$I$2,'Boulder Invoice'!$E:$E,$A13) -> 26201.96 | F13: 0 | G13: =+SUM(D13,E13,F13) -> 629748.76 | H13: =+IFERROR(G13/C13,0) -> 0.96884424 | I13: =+C13-G13 -> 20251.242 | J13: =+SUMIFS('Boulder Invoice'!$I:$I,'Boulder Invoice'!$B:$B,"<="&$I$2,'Boulder Invoice'!$E:$E,$A13) -> 0
A14: 2 | B14: SITEWORK | C14: 886000 | D14: =+SUMIFS('Boulder Invoice'!$H:$H,'Boulder Invoice'!$B:$B,"<"&$I$2,'Boulder Invoice'!$E:$E,$A14) -> 886000 | E14: =+SUMIFS('Boulder Invoice'!$H:$H,'Boulder Invoice'!$B:$B,$I$2,'Boulder Invoice'!$E:$E,$A14) -> 0 | F14: 0 | G14: =+SUM(D14,E14,F14) -> 886000 | H14: =+IFERROR(G14/C14,0) -> 1 | I14: =+C14-G14 -> -0.0043055558 | J14: =+SUMIFS('Boulder Invoice'!$I:$I,'Boulder Invoice'!$B:$B,"<="&$I$2,'Boulder Invoice'!$E:$E,$A14) -> 13347.746
A15: 3 | B15: CONCRETE | C15: 1074000 | D15: =+SUMIFS('Boulder Invoice'!$H:$H,'Boulder Invoice'!$B:$B,"<"&$I$2,'Boulder Invoice'!$E:$E,$A15) -> 952636.72 | E15: =+SUMIFS('Boulder Invoice'!$H:$H,'Boulder Invoice'!$B:$B,$I$2,'Boulder Invoice'!$E:$E,$A15) -> 84710.29 | F15: 0 | G15: =+SUM(D15,E15,F15) -> 1037347 | H15: =+IFERROR(G15/C15,0) -> 0.96587245 | I15: =+C15-G15 -> 36652.99 | J15: =+SUMIFS('Boulder Invoice'!$I:$I,'Boulder Invoice'!$B:$B,"<="&$I$2,'Boulder Invoice'!$E:$E,$A15) -> 47363
A16: 4 | B16: MASONRY | C16: 9000 | D16: =+SUMIFS('Boulder Invoice'!$H:$H,'Boulder Invoice'!$B:$B,"<"&$I$2,'Boulder Invoice'!$E:$E,$A16) -> 8964.51 | E16: =+SUMIFS('Boulder Invoice'!$H:$H,'Boulder Invoice'!$B:$B,$I$2,'Boulder Invoice'!$E:$E,$A16) -> 0 | F16: 0 | G16: =+SUM(D16,E16,F16) -> 8964.51 | H16: =+IFERROR(G16/C16,0) -> 0.99605667 | I16: =+C16-G16 -> 35.49 | J16: =+SUMIFS('Boulder Invoice'!$I:$I,'Boulder Invoice'!$B:$B,"<="&$I$2,'Boulder Invoice'!$E:$E,$A16) -> 800
A17: 5 | B17: METALS | C17: 155000 | D17: =+SUMIFS('Boulder Invoice'!$H:$H,'Boulder Invoice'!$B:$B,"<"&$I$2,'Boulder Invoice'!$E:$E,$A17) -> 92352.34 | E17: =+SUMIFS('Boulder Invoice'!$H:$H,'Boulder Invoice'!$B:$B,$I$2,'Boulder Invoice'!$E:$E,$A17) -> 8284.57 | F17: 0 | G17: =+SUM(D17,E17,F17) -> 100636.91 | H17: =+IFERROR(G17/C17,0) -> 0.64927039 | I17: =+C17-G17 -> 54363.09 | J17: =+SUMIFS('Boulder Invoice'!$I:$I,'Boulder Invoice'!$B:$B,"<="&$I$2,'Boulder Invoice'!$E:$E,$A17) -> 5167.5
A18: 6 | B18: WOOD, PLASTICS AND COMPOSITES | C18: 1301000 | D18: =+SUMIFS('Boulder Invoice'!$H:$H,'Boulder Invoice'!$B:$B,"<"&$I$2,'Boulder Invoice'!$E:$E,$A18) -> 1301000 | E18: =+SUMIFS('Boulder Invoice'!$H:$H,'Boulder Invoice'!$B:$B,$I$2,'Boulder Invoice'!$E:$E,$A18) -> 0 | F18: 0 | G18: =+SUM(D18,E18,F18) -> 1301000 | H18: =+IFERROR(G18/C18,0) -> 1 | I18: =+C18-G18 -> -1.8626451e-09 | J18: =+SUMIFS('Boulder Invoice'!$I:$I,'Boulder Invoice'!$B:$B,"<="&$I$2,'Boulder Invoice'!$E:$E,$A18) -> 37147.813
A19: 7 | B19: THERMAL AND MOISTURE PROTECTION | C19: 1006000 | D19: =+SUMIFS('Boulder Invoice'!$H:$H,'Boulder Invoice'!$B:$B,"<"&$I$2,'Boulder Invoice'!$E:$E,$A19) -> 971543.17 | E19: =+SUMIFS('Boulder Invoice'!$H:$H,'Boulder Invoice'!$B:$B,$I$2,'Boulder Invoice'!$E:$E,$A19) -> 22887.23 | F19: 0 | G19: =+SUM(D19,E19,F19) -> 994430.4 | H19: =+IFERROR(G19/C19,0) -> 0.9884994 | I19: =+C19-G19 -> 11569.604 | J19: =+SUMIFS('Boulder Invoice'!$I:$I,'Boulder Invoice'!$B:$B,"<="&$I$2,'Boulder Invoice'!$E:$E,$A19) -> 81440.493
A20: 8 | B20: OPENINGS | C20: 805000 | D20: =+SUMIFS('Boulder Invoice'!$H:$H,'Boulder Invoice'!$B:$B,"<"&$I$2,'Boulder Invoice'!$E:$E,$A20) -> 517620.48 | E20: =+SUMIFS('Boulder Invoice'!$H:$H,'Boulder Invoice'!$B:$B,$I$2,'Boulder Invoice'!$E:$E,$A20) -> 167429.52 | F20: 0 | G20: =+SUM(D20,E20,F20) -> 685050 | H20: =+IFERROR(G20/C20,0) -> 0.85099379 | I20: =+C20-G20 -> 119950 | J20: =+SUMIFS('Boulder Invoice'!$I:$I,'Boulder Invoice'!$B:$B,"<="&$I$2,'Boulder Invoice'!$E:$E,$A20) -> 1887.5
A21: 9 | B21: FINISHES | C21: 1040000 | D21: =+SUMIFS('Boulder Invoice'!$H:$H,'Boulder Invoice'!$B:$B,"<"&$I$2,'Boulder Invoice'!$E:$E,$A21) -> 899100.26 | E21: =+SUMIFS('Boulder Invoice'!$H:$H,'Boulder Invoice'!$B:$B,$I$2,'Boulder Invoice'!$E:$E,$A21) -> 67800.31 | F21: 0 | G21: =+SUM(D21,E21,F21) -> 966900.57 | H21: =+IFERROR(G21/C21,0) -> 0.92971209 | I21: =+C21-G21 -> 73099.43 | J21: =+SUMIFS('Boulder Invoice'!$I:$I,'Boulder Invoice'!$B:$B,"<="&$I$2,'Boulder Invoice'!$E:$E,$A21) -> 66615
A22: 10 | B22: SPECIALTIES AND EQUIPMENT | C22: 430000 | D22: =+SUMIFS('Boulder Invoice'!$H:$H,'Boulder Invoice'!$B:$B,"<"&$I$2,'Boulder Invoice'!$E:$E,$A22) -> 392687.33 | E22: =+SUMIFS('Boulder Invoice'!$H:$H,'Boulder Invoice'!$B:$B,$I$2,'Boulder Invoice'!$E:$E,$A22) -> 12912.44 | F22: 0 | G22: =+SUM(D22,E22,F22) -> 405599.77 | H22: =+IFERROR(G22/C22,0) -> 0.94325528 | I22: =+C22-G22 -> 24400.23 | J22: =+SUMIFS('Boulder Invoice'!$I:$I,'Boulder Invoice'!$B:$B,"<="&$I$2,'Boulder Invoice'!$E:$E,$A22) -> 0
A23: 11 | B23: FURNISHINGS | C23: 290000 | D23: =+SUMIFS('Boulder Invoice'!$H:$H,'Boulder Invoice'!$B:$B,"<"&$I$2,'Boulder Invoice'!$E:$E,$A23) -> 182625.92 | E23: =+SUMIFS('Boulder Invoice'!$H:$H,'Boulder Invoice'!$B:$B,$I$2,'Boulder Invoice'!$E:$E,$A23) -> 41539.63 | F23: 0 | G23: =+SUM(D23,E23,F23) -> 224165.55 | H23: =+IFERROR(G23/C23,0) -> 0.77298466 | I23: =+C23-G23 -> 65834.45 | J23: =+SUMIFS('Boulder Invoice'!$I:$I,'Boulder Invoice'!$B:$B,"<="&$I$2,'Boulder Invoice'!$E:$E,$A23) -> 0
A24: 12 | B24: SWIMMING POOL | C24: 215000 | D24: =+SUMIFS('Boulder Invoice'!$H:$H,'Boulder Invoice'!$B:$B,"<"&$I$2,'Boulder Invoice'!$E:$E,$A24) -> 130472.62 | E24: =+SUMIFS('Boulder Invoice'!$H:$H,'Boulder Invoice'!$B:$B,$I$2,'Boulder Invoice'!$E:$E,$A24) -> 76391.08 | F24: 0 | G24: =+SUM(D24,E24,F24) -> 206863.7 | H24: =+IFERROR(G24/C24,0) -> 0.96215674 | I24: =+C24-G24 -> 8136.3011 | J24: =+SUMIFS('Boulder Invoice'!$I:$I,'Boulder Invoice'!$B:$B,"<="&$I$2,'Boulder Invoice'!$E:$E,$A24) -> 14294.599
... A30: 18 | B30: CONTRACTOR'S FEE | C30: 300000 | D30: =+SUMIFS('Boulder Invoice'!$H:$H,'Boulder Invoice'!$B:$B,"<"&$I$2,'Boulder Invoice'!$E:$E,$A30) -> 283333.33 | E30: =+SUMIFS('Boulder Invoice'!$H:$H,'Boulder Invoice'!$B:$B,$I$2,'Boulder Invoice'!$E:$E,$A30) -> 0 | F30: 0 | G30: =+SUM(D30,E30,F30) -> 283333.33 | H30: =+IFERROR(G30/C30,0) -> 0.94444444 | I30: =+C30-G30 -> 16666.667 | J30: =+SUMIFS('Boulder Invoice'!$I:$I,'Boulder Invoice'!$B:$B,"<="&$I$2,'Boulder Invoice'!$E:$E,$A30) -> 28333.333
B32: GRAND TOTAL | C32: =+SUM(C13:C31) -> 11800000 | D32: =+SUM(D13:D31) -> 10589688 | E32: =+SUM(E13:E31) -> 757596.85 | F32: =+SUM(F13:F31) -> 0 | G32: =+SUM(G13:G31) -> 11347285 | H32: =+IFERROR(G32/C32,0) -> 0.96163434 | I32: =+SUM(I13:I31) -> 452714.78 | J32: =+SUM(J13:J31) -> 539680.01
A33: Users may obtain validation of this document by requesting of the license a completed AIA Document D401 - Certification of Document's Authenticity

Sheet Boulder Invoice
M2: Print
M3: =+'G702'!P3 -> 0
E6: Boulder Construction | J6: Invoice / Payment Voucher
E7: Divine Force I, LLC
E8: 2775 Villa Creek Dr, Suite B-240 | I8: Invoice # | J8: Date
E9: Farmers Branch, TX 75234 | I9: 1017 | J9: 46086
E10: (561) 889-4988
E11: admin@boulderconstruction.com
E14: Bill To:
E15: Prevail Waxahachie, LLC
E16: 205 Murphy Drive
E17: Southlake, Texas 76092
E19: Paid
B20: Draw | E20: G703 # | F20: Description | G20: Commentary | H20: Amount | I20: Retainage | J20: Net Amount
B22: 17 | E22: 1 | F22: Jobsite Office - Recurring Rental | G22: From Willscott | H22: 160.4 | I22: 0 | J22: =H22-I22 -> 160.4 | M22: 12205
B23: 17 | E23: 1 | F23: Misc. Jobsite Material Expenses | G23: From Home Depot - Mount Starter Kit with Ball and Lock | H23: 72.47 | I23: 0 | J23: =H23-I23 -> 72.47 | M23: 12212
B24: 17 | E24: 1 | F24: Misc. Jobsite Material Expenses | G24: From Home Depot - Bottled Water And Utility Knife, Blades | H24: 60.9 | I24: 0 | J24: =H24-I24 -> 60.9 | M24: 12221
B25: 17 | E25: 1 | F25: Final Cleaning Supplies | G25: From Home Depot - Jobsite Cleaning SuppliesCleaning Wipes and Cleaners | H25: 104.83 | I25: 0 | J25: =H25-I25 -> 104.83 | M25: 12248
B26: 17 | E26: 1 | F26: Temporary Toilets - Recurring Payment | G26: A-1 Little John | H26: 954.77 | I26: 0 | J26: =H26-I26 -> 954.77 | M26: 12258
B27: 17 | E27: 1 | F27: Jobsite Dumpster | G27: From Advantage Waste Disposal | H27: 1449.48 | I27: 0 | J27: =H27-I27 -> 1449.48 | M27: 12260
B28: 17 | E28: 1 | F28: Jobsite Office - Recurring Rental | G28: From Willscott | H28: 677.87 | I28: 0 | J28: =H28-I28 -> 677.87 | M28: 12269
B29: 17 | E29: 1 | F29: Jobsite Office - Recurring Rental | G29: From Willscott | H29: 136.31 | I29: 0 | J29: =H29-I29 -> 136.31 | M29: 12270
B30: 17 | E30: 1 | F30: Jobsite Office - Recurring Rental | G30: From Willscott | H30: 420.28 | I30: 0 | J30: =H30-I30 -> 420.28 | M30: 12271
B31: 17 | E31: 1 | F31: Jobsite Dumpster | G31: From Waste Connections | H31: 2105.22 | I31: 0 | J31: =H31-I31 -> 2105.22 | M31: 12274
B32: 17 | E32: 1 | F32: Jobsite Dumpster | G32: From Waste Connections | H32: 1613.43 | I32: 0 | J32: =H32-I32 -> 1613.43 | M32: 12275
B33: 17 | E33: 1 | F33: Jobsite Office - Recurring Rental | G33: From Willscott | H33: 24.09 | I33: 0 | J33: =H33-I33 -> 24.09 | M33: 12286
... B38: 17 | E38: 1 | F38: Jobsite Dumpster | G38: From Advantage Waste Disposal | H38: 1449.48 | I38: 0 | J38: =H38-I38 -> 1449.48 | M38: 12492
B39: 17 | E39: 1 | F39: Notary Fees | G39: For Draw | H39: 13.46 | I39: 0 | J39: =H39-I39 -> 13.46 | M39: [TBD]
B40: 17 | E40: 1 | F40: Jobsite Dumpster | G40: From Waste Connections | H40: -491.79 | I40: 0 | J40: =H40-I40 -> -491.79 | M40: [TBD]
B41: 17 | E41: 1 | F41: Jobsite Material Refund | G41: From Home Depot - Refund | H41: -11.08 | I41: 0 | J41: =H41-I41 -> -11.08 | M41: [TBD]
B42: 17 | E42: 1 | F42: Jobsite Material Refund | G42: From Home Depot - Refund | H42: -57.68 | I42: 0 | J42: =H42-I42 -> -57.68 | M42: [TBD]
B43: 17 | E43: 1 | F43: Jobsite Material Refund | G43: From Home Depot - Refund | H43: -855.97 | I43: 0 | J43: =H43-I43 -> -855.97 | M43: [TBD]
B44: 17 | E44: 1 | F44: Notary Fees | G44: For Draw | H44: 25 | I44: 0 | J44: =H44-I44 -> 25 | M44: [TBD]
B45: 17 | E45: 1 | F45: Notary Fees | G45: For Draw | H45: 25 | I45: 0 | J45: =H45-I45 -> 25 | M45: [TBD]
B46: 17 | E46: 1 | F46: Travel for Labor During Ice Storm | G46: From Lyft | H46: 66.95 | I46: 0 | J46: =H46-I46 -> 66.95 | M46: [TBD]
B47: 17 | E47: 1 | F47: Travel for Labor During Ice Storm | G47: From Lyft | H47: 44.94 | I47: 0 | J47: =H47-I47 -> 44.94 | M47: [TBD]
B48: 17 | E48: 1 | F48: Travel for Labor During Ice Storm | G48: From Lyft | H48: 46.96 | I48: 0 | J48: =H48-I48 -> 46.96 | M48: [TBD]
B49: 17 | E49: 1 | F49: Travel for Labor During Ice Storm | G49: From Lyft | H49: 63.93 | I49: 0 | J49: =H49-I49 -> 63.93 | M49: [TBD]
B50: 17 | E50: 1 | F50: Travel for Labor During Ice Storm | G50: From Lyft | H50: 49.93 | I50: 0 | J50: =H50-I50 -> 49.93 | M50: [TBD]
... B63: 17 | E63: 1 | F63: Cellular Data & WiFi for Jobsite Office - True Up | G63: From AT&T | H63: 303.81 | I63: 0 | J63: =H63-I63 -> 303.81 | M63: [TBD]
...
